[2025-07-13T18:51:56.039+0000] {taskinstance.py:1956} INFO - Dependencies all met for dep_context=non-requeueable deps ti=<TaskInstance: data_extraction_to_snowflake.processing_tables manual__2025-07-13T18:51:53.502743+00:00 map_index=0 [queued]>
[2025-07-13T18:51:56.043+0000] {taskinstance.py:1956} INFO - Dependencies all met for dep_context=requeueable deps ti=<TaskInstance: data_extraction_to_snowflake.processing_tables manual__2025-07-13T18:51:53.502743+00:00 map_index=0 [queued]>
[2025-07-13T18:51:56.043+0000] {taskinstance.py:2170} INFO - Starting attempt 1 of 1
[2025-07-13T18:51:56.051+0000] {taskinstance.py:2191} INFO - Executing <Mapped(_PythonDecoratedOperator): processing_tables> on 2025-07-13 18:51:53.502743+00:00
[2025-07-13T18:51:56.054+0000] {standard_task_runner.py:60} INFO - Started process 424 to run task
[2025-07-13T18:51:56.057+0000] {standard_task_runner.py:87} INFO - Running: ['***', 'tasks', 'run', 'data_extraction_to_snowflake', 'processing_tables', 'manual__2025-07-13T18:51:53.502743+00:00', '--job-id', '40', '--raw', '--subdir', 'DAGS_FOLDER/etl_transfer_to_stage.py', '--cfg-path', '/tmp/tmpnjdsy2_k', '--map-index', '0']
[2025-07-13T18:51:56.060+0000] {standard_task_runner.py:88} INFO - Job 40: Subtask processing_tables
[2025-07-13T18:51:56.111+0000] {task_command.py:423} INFO - Running <TaskInstance: data_extraction_to_snowflake.processing_tables manual__2025-07-13T18:51:53.502743+00:00 map_index=0 [running]> on host ba480c39b9ec
[2025-07-13T18:51:56.170+0000] {taskinstance.py:2480} INFO - Exporting env vars: AIRFLOW_CTX_DAG_OWNER='***' AIRFLOW_CTX_DAG_ID='data_extraction_to_snowflake' AIRFLOW_CTX_TASK_ID='processing_tables' AIRFLOW_CTX_EXECUTION_DATE='2025-07-13T18:51:53.502743+00:00' AIRFLOW_CTX_TRY_NUMBER='1' AIRFLOW_CTX_DAG_RUN_ID='manual__2025-07-13T18:51:53.502743+00:00'
[2025-07-13T18:51:56.180+0000] {taskinstance.py:2698} ERROR - Task failed with exception
Traceback (most recent call last):
  File "/home/airflow/.local/lib/python3.8/site-packages/airflow/models/taskinstance.py", line 433, in _execute_task
    result = execute_callable(context=context, **execute_callable_kwargs)
  File "/home/airflow/.local/lib/python3.8/site-packages/airflow/decorators/base.py", line 241, in execute
    return_value = super().execute(context)
  File "/home/airflow/.local/lib/python3.8/site-packages/airflow/operators/python.py", line 199, in execute
    return_value = self.execute_callable()
  File "/home/airflow/.local/lib/python3.8/site-packages/airflow/operators/python.py", line 216, in execute_callable
    return self.python_callable(*self.op_args, **self.op_kwargs)
  File "/opt/airflow/dags/etl_transfer_to_stage.py", line 45, in processing_each_table
    with SnowflakeHook(snowflake_conn_id='snowflake').get_conn() as snow_conn:
  File "/home/airflow/.local/lib/python3.8/site-packages/airflow/providers/snowflake/hooks/snowflake.py", line 275, in get_conn
    conn_config = self._get_conn_params()
  File "/home/airflow/.local/lib/python3.8/site-packages/airflow/providers/snowflake/hooks/snowflake.py", line 183, in _get_conn_params
    conn = self.get_connection(self.snowflake_conn_id)  # type: ignore[attr-defined]
  File "/home/airflow/.local/lib/python3.8/site-packages/airflow/hooks/base.py", line 82, in get_connection
    conn = Connection.get_connection_from_secrets(conn_id)
  File "/home/airflow/.local/lib/python3.8/site-packages/airflow/models/connection.py", line 479, in get_connection_from_secrets
    raise AirflowNotFoundException(f"The conn_id `{conn_id}` isn't defined")
airflow.exceptions.AirflowNotFoundException: The conn_id `snowflake` isn't defined
[2025-07-13T18:51:56.184+0000] {taskinstance.py:1138} INFO - Marking task as FAILED. dag_id=data_extraction_to_snowflake, task_id=processing_tables, map_index=0, execution_date=20250713T185153, start_date=20250713T185156, end_date=20250713T185156
[2025-07-13T18:51:56.190+0000] {standard_task_runner.py:107} ERROR - Failed to execute job 40 for task processing_tables (The conn_id `snowflake` isn't defined; 424)
[2025-07-13T18:51:56.198+0000] {local_task_job_runner.py:234} INFO - Task exited with return code 1
[2025-07-13T18:51:56.207+0000] {taskinstance.py:3280} INFO - 0 downstream tasks scheduled from follow-on schedule check
