[2025-07-27T14:18:35.610+0000] {taskinstance.py:1956} INFO - Dependencies all met for dep_context=non-requeueable deps ti=<TaskInstance: data_extraction_to_snowflake.processing_tables scheduled__2025-07-19T00:00:00+00:00 map_index=0 [queued]>
[2025-07-27T14:18:35.635+0000] {taskinstance.py:1956} INFO - Dependencies all met for dep_context=requeueable deps ti=<TaskInstance: data_extraction_to_snowflake.processing_tables scheduled__2025-07-19T00:00:00+00:00 map_index=0 [queued]>
[2025-07-27T14:18:35.637+0000] {taskinstance.py:2170} INFO - Starting attempt 1 of 1
[2025-07-27T14:18:35.673+0000] {taskinstance.py:2191} INFO - Executing <Mapped(_PythonDecoratedOperator): processing_tables> on 2025-07-19 00:00:00+00:00
[2025-07-27T14:18:35.679+0000] {standard_task_runner.py:60} INFO - Started process 125 to run task
[2025-07-27T14:18:35.690+0000] {standard_task_runner.py:87} INFO - Running: ['***', 'tasks', 'run', 'data_extraction_to_snowflake', 'processing_tables', 'scheduled__2025-07-19T00:00:00+00:00', '--job-id', '197', '--raw', '--subdir', 'DAGS_FOLDER/etl_transfer_to_stage.py', '--cfg-path', '/tmp/tmpbss6f46_', '--map-index', '0']
[2025-07-27T14:18:35.696+0000] {standard_task_runner.py:88} INFO - Job 197: Subtask processing_tables
[2025-07-27T14:18:35.799+0000] {task_command.py:423} INFO - Running <TaskInstance: data_extraction_to_snowflake.processing_tables scheduled__2025-07-19T00:00:00+00:00 map_index=0 [running]> on host ba480c39b9ec
[2025-07-27T14:18:35.997+0000] {taskinstance.py:2480} INFO - Exporting env vars: AIRFLOW_CTX_DAG_OWNER='***' AIRFLOW_CTX_DAG_ID='data_extraction_to_snowflake' AIRFLOW_CTX_TASK_ID='processing_tables' AIRFLOW_CTX_EXECUTION_DATE='2025-07-19T00:00:00+00:00' AIRFLOW_CTX_TRY_NUMBER='1' AIRFLOW_CTX_DAG_RUN_ID='scheduled__2025-07-19T00:00:00+00:00'
[2025-07-27T14:18:35.999+0000] {etl_transfer_to_stage.py:56} INFO - Starting transfer data from table job_info
[2025-07-27T14:18:36.022+0000] {taskinstance.py:2698} ERROR - Task failed with exception
Traceback (most recent call last):
  File "/opt/airflow/dags/etl_transfer_to_stage.py", line 59, in processing_each_table
    with SnowflakeHook(snowflake_conn_id='snowflake').get_conn() as snow_conn:
  File "/home/airflow/.local/lib/python3.8/site-packages/airflow/providers/snowflake/hooks/snowflake.py", line 275, in get_conn
    conn_config = self._get_conn_params()
  File "/home/airflow/.local/lib/python3.8/site-packages/airflow/providers/snowflake/hooks/snowflake.py", line 183, in _get_conn_params
    conn = self.get_connection(self.snowflake_conn_id)  # type: ignore[attr-defined]
  File "/home/airflow/.local/lib/python3.8/site-packages/airflow/hooks/base.py", line 82, in get_connection
    conn = Connection.get_connection_from_secrets(conn_id)
  File "/home/airflow/.local/lib/python3.8/site-packages/airflow/models/connection.py", line 479, in get_connection_from_secrets
    raise AirflowNotFoundException(f"The conn_id `{conn_id}` isn't defined")
airflow.exceptions.AirflowNotFoundException: The conn_id `snowflake` isn't defined

During handling of the above exception, another exception occurred:

Traceback (most recent call last):
  File "/home/airflow/.local/lib/python3.8/site-packages/airflow/models/taskinstance.py", line 433, in _execute_task
    result = execute_callable(context=context, **execute_callable_kwargs)
  File "/home/airflow/.local/lib/python3.8/site-packages/airflow/decorators/base.py", line 241, in execute
    return_value = super().execute(context)
  File "/home/airflow/.local/lib/python3.8/site-packages/airflow/operators/python.py", line 199, in execute
    return_value = self.execute_callable()
  File "/home/airflow/.local/lib/python3.8/site-packages/airflow/operators/python.py", line 216, in execute_callable
    return self.python_callable(*self.op_args, **self.op_kwargs)
  File "/opt/airflow/dags/etl_transfer_to_stage.py", line 69, in processing_each_table
    raise AirflowException(f"Failed on collecting the max_id from table {table_name}: {e}")
airflow.exceptions.AirflowException: Failed on collecting the max_id from table job_info: The conn_id `snowflake` isn't defined
[2025-07-27T14:18:36.030+0000] {taskinstance.py:1138} INFO - Marking task as FAILED. dag_id=data_extraction_to_snowflake, task_id=processing_tables, map_index=0, execution_date=20250719T000000, start_date=20250727T141835, end_date=20250727T141836
[2025-07-27T14:18:36.065+0000] {standard_task_runner.py:107} ERROR - Failed to execute job 197 for task processing_tables (Failed on collecting the max_id from table job_info: The conn_id `snowflake` isn't defined; 125)
[2025-07-27T14:18:36.117+0000] {local_task_job_runner.py:234} INFO - Task exited with return code 1
[2025-07-27T14:18:36.131+0000] {taskinstance.py:3280} INFO - 0 downstream tasks scheduled from follow-on schedule check
