[2025-07-13T18:48:36.486+0000] {taskinstance.py:1956} INFO - Dependencies all met for dep_context=non-requeueable deps ti=<TaskInstance: data_extraction_to_snowflake.processing_tables manual__2025-07-13T18:48:34.030955+00:00 map_index=0 [queued]>
[2025-07-13T18:48:36.491+0000] {taskinstance.py:1956} INFO - Dependencies all met for dep_context=requeueable deps ti=<TaskInstance: data_extraction_to_snowflake.processing_tables manual__2025-07-13T18:48:34.030955+00:00 map_index=0 [queued]>
[2025-07-13T18:48:36.491+0000] {taskinstance.py:2170} INFO - Starting attempt 1 of 1
[2025-07-13T18:48:36.499+0000] {taskinstance.py:2191} INFO - Executing <Mapped(_PythonDecoratedOperator): processing_tables> on 2025-07-13 18:48:34.030955+00:00
[2025-07-13T18:48:36.502+0000] {standard_task_runner.py:60} INFO - Started process 322 to run task
[2025-07-13T18:48:36.508+0000] {standard_task_runner.py:87} INFO - Running: ['***', 'tasks', 'run', 'data_extraction_to_snowflake', 'processing_tables', 'manual__2025-07-13T18:48:34.030955+00:00', '--job-id', '26', '--raw', '--subdir', 'DAGS_FOLDER/etl_transfer_to_stage.py', '--cfg-path', '/tmp/tmp2wgv3s05', '--map-index', '0']
[2025-07-13T18:48:36.511+0000] {standard_task_runner.py:88} INFO - Job 26: Subtask processing_tables
[2025-07-13T18:48:36.558+0000] {task_command.py:423} INFO - Running <TaskInstance: data_extraction_to_snowflake.processing_tables manual__2025-07-13T18:48:34.030955+00:00 map_index=0 [running]> on host ba480c39b9ec
[2025-07-13T18:48:36.596+0000] {taskinstance.py:2698} ERROR - Task failed with exception
Traceback (most recent call last):
  File "/home/airflow/.local/lib/python3.8/site-packages/airflow/models/taskinstance.py", line 2334, in _run_raw_task
    self._execute_task_with_callbacks(context, test_mode, session=session)
  File "/home/airflow/.local/lib/python3.8/site-packages/airflow/models/taskinstance.py", line 2465, in _execute_task_with_callbacks
    task_orig = self.render_templates(context=context)
  File "/home/airflow/.local/lib/python3.8/site-packages/airflow/models/taskinstance.py", line 2877, in render_templates
    original_task.render_template_fields(context)
  File "/home/airflow/.local/lib/python3.8/site-packages/airflow/models/mappedoperator.py", line 732, in render_template_fields
    unmapped_task = self.unmap(mapped_kwargs)
  File "/home/airflow/.local/lib/python3.8/site-packages/airflow/models/mappedoperator.py", line 649, in unmap
    op = self.operator_class(**kwargs, _airflow_from_mapped=True)
  File "/home/airflow/.local/lib/python3.8/site-packages/airflow/models/baseoperator.py", line 437, in apply_defaults
    result = func(self, **kwargs, default_args=default_args)
  File "/home/airflow/.local/lib/python3.8/site-packages/airflow/decorators/python.py", line 52, in __init__
    super().__init__(
  File "/home/airflow/.local/lib/python3.8/site-packages/airflow/models/baseoperator.py", line 437, in apply_defaults
    result = func(self, **kwargs, default_args=default_args)
  File "/home/airflow/.local/lib/python3.8/site-packages/airflow/decorators/base.py", line 233, in __init__
    super().__init__(task_id=task_id, **kwargs_to_upstream, **kwargs)
  File "/home/airflow/.local/lib/python3.8/site-packages/airflow/models/baseoperator.py", line 437, in apply_defaults
    result = func(self, **kwargs, default_args=default_args)
  File "/home/airflow/.local/lib/python3.8/site-packages/airflow/operators/python.py", line 184, in __init__
    super().__init__(**kwargs)
  File "/home/airflow/.local/lib/python3.8/site-packages/airflow/models/baseoperator.py", line 437, in apply_defaults
    result = func(self, **kwargs, default_args=default_args)
  File "/home/airflow/.local/lib/python3.8/site-packages/airflow/models/baseoperator.py", line 793, in __init__
    raise AirflowException(
airflow.exceptions.AirflowException: Invalid arguments were passed to _PythonDecoratedOperator (task_id: processing_tables__1). Invalid arguments were:
**kwargs: {'depends_one': False, 'max_active_runs': 1}
[2025-07-13T18:48:36.599+0000] {taskinstance.py:2744} ERROR - Unable to unmap task to determine if we need to send an alert email
[2025-07-13T18:48:36.600+0000] {taskinstance.py:1138} INFO - Marking task as FAILED. dag_id=data_extraction_to_snowflake, task_id=processing_tables, map_index=0, execution_date=20250713T184834, start_date=20250713T184836, end_date=20250713T184836
[2025-07-13T18:48:36.606+0000] {standard_task_runner.py:107} ERROR - Failed to execute job 26 for task processing_tables (Invalid arguments were passed to _PythonDecoratedOperator (task_id: processing_tables__1). Invalid arguments were:
**kwargs: {'depends_one': False, 'max_active_runs': 1}; 322)
[2025-07-13T18:48:36.646+0000] {local_task_job_runner.py:234} INFO - Task exited with return code 1
[2025-07-13T18:48:36.653+0000] {taskinstance.py:3280} INFO - 0 downstream tasks scheduled from follow-on schedule check
